\\u001b\[[\d;]*m
(File .*\.py:[\d]*,) 
$1\n\t
\t

{
	"name": "RuntimeError",
	"message": "Exception encountered when calling layer \"gradient_layer\" (type GradientLayer).

KeyError: 'c'

Call arguments received by layer \"gradient_layer\" (type GradientLayer):
  • x=tf.Tensor(shape=(None, 2), dtype=float32)",
	"stack": "---------------------------------------------------------------------------
RuntimeError                              Traceback (most recent call last)
Cell In[11], line 1
----> 1 pinns = [PINN(n, **p).build(**p) for n, p in zip(networks, params)]
      2 for pinn in pinns:
      3     pinn.compile(optimizer=optimizer, loss=loss)

Cell In[11], line 1, in <listcomp>(.0)
----> 1 pinns = [PINN(n, **p).build(**p) for n, p in zip(networks, params)]
      2 for pinn in pinns:
      3     pinn.compile(optimizer=optimizer, loss=loss)

File c:\\Users\\kust\\Diplom\\my_pinn\\lib\\pinn.py:30,
	 in PINN.build(self, nu, z, l, kT, ro, e, p_grd, Fi_left, Fi_right, c_left, c_right, c_start, v_left, v_right, v_start, **kwargs)
     23 ins.append(tf.keras.layers.Input(1))                         # Fi_start
     25 outs = []
     27 c, c_t, c_grd, \\
     28     v_t, v_div, v_adv, v_lap, \\
     29     Fi_grd, Fi_lap, j_div = \\
---> 30     self.grads(ins[0])
     31 outs.append(c_t + j_div)
     32 outs.append(Fi_lap + 4*pi*l*kT*(z*c))

File ~\\AppData\\Local\\Packages\\PythonSoftwareFoundation.Python.3.10_qbz5n2kfra8p0\\LocalCache\\local-packages\\Python310\\site-packages\\keras\\utils\\traceback_utils.py:70,
	 in filter_traceback.<locals>.error_handler(*args, **kwargs)
     67     filtered_tb = _process_traceback_frames(e.__traceback__)
     68     # To get the full stack trace, call:
     69     # `tf.debugging.disable_traceback_filtering()`
---> 70     raise e.with_traceback(filtered_tb) from None
     71 finally:
     72     del filtered_tb

File ~\\AppData\\Local\\Temp\\__autograph_generated_fileorokvodw.py:35,
	 in outer_factory.<locals>.inner_factory.<locals>.tf__call(self, x)
     33     ag__.converted_call(ag__.ld(g).watch, (ag__.ld(x),), None, fscope)
     34     r = ag__.converted_call(ag__.ld(self).model, (ag__.ld(x),), None, fscope)
---> 35     (c, v, Fi) = (ag__.ld(r)['c'], ag__.ld(r)['v'], ag__.ld(r)['Fi'])
     36 ag__.converted_call(ag__.ld(print_t), (ag__.ld(c),), dict(debug=ag__.ld(print_debug)), fscope)
     37 c_jac = ag__.converted_call(ag__.ld(g).batch_jacobian, (ag__.ld(c), ag__.ld(x)), None, fscope)[..., 0, :]

RuntimeError: Exception encountered when calling layer \"gradient_layer\" (type GradientLayer).

KeyError: 'c'

Call arguments received by layer \"gradient_layer\" (type GradientLayer):
  • x=tf.Tensor(shape=(None, 2), dtype=float32)"
}